Traceback (most recent call last):
  File "/home/creative/miniconda3/envs/jupyter-book/lib/python3.9/site-packages/jupyter_cache/executors/utils.py", line 51, in single_nb_execution
    executenb(
  File "/home/creative/miniconda3/envs/jupyter-book/lib/python3.9/site-packages/nbclient/client.py", line 1112, in execute
    return NotebookClient(nb=nb, resources=resources, km=km, **kwargs).execute()
  File "/home/creative/miniconda3/envs/jupyter-book/lib/python3.9/site-packages/nbclient/util.py", line 74, in wrapped
    return just_run(coro(*args, **kwargs))
  File "/home/creative/miniconda3/envs/jupyter-book/lib/python3.9/site-packages/nbclient/util.py", line 53, in just_run
    return loop.run_until_complete(coro)
  File "/home/creative/miniconda3/envs/jupyter-book/lib/python3.9/asyncio/base_events.py", line 642, in run_until_complete
    return future.result()
  File "/home/creative/miniconda3/envs/jupyter-book/lib/python3.9/site-packages/nbclient/client.py", line 553, in async_execute
    await self.async_execute_cell(
  File "/home/creative/miniconda3/envs/jupyter-book/lib/python3.9/site-packages/nbclient/client.py", line 857, in async_execute_cell
    self._check_raise_for_error(cell, exec_reply)
  File "/home/creative/miniconda3/envs/jupyter-book/lib/python3.9/site-packages/nbclient/client.py", line 760, in _check_raise_for_error
    raise CellExecutionError.from_cell_and_msg(cell, exec_reply_content)
nbclient.exceptions.CellExecutionError: An error occurred while executing the following cell:
------------------
import torch
import numpy as np
def synthetic_data(w, b, num_examples):
    '''generate y = Xw + b + noise'''
    X = np.random.normal(scale=1, size=(num_examples, len(w)))
    y = np.dot(X, w) + b
    y += np.random.normal(scale=0.01, size=y.shape)
    X = torch.from_numpy(X).float()
    y = torch.from_numpy(y).float().reshape(-1, 1)
    return X, y

true_w = torch.Tensor([2, -3.4])
true_b = 4.2
features, labels = synthetic_data(true_w, true_b, 1000)
------------------

[0;31m---------------------------------------------------------------------------[0m
[0;31mModuleNotFoundError[0m                       Traceback (most recent call last)
[0;32m<ipython-input-1-88928b6c6a65>[0m in [0;36m<module>[0;34m[0m
[0;32m----> 1[0;31m [0;32mimport[0m [0mtorch[0m[0;34m[0m[0;34m[0m[0m
[0m[1;32m      2[0m [0;32mimport[0m [0mnumpy[0m [0;32mas[0m [0mnp[0m[0;34m[0m[0;34m[0m[0m
[1;32m      3[0m [0;32mdef[0m [0msynthetic_data[0m[0;34m([0m[0mw[0m[0;34m,[0m [0mb[0m[0;34m,[0m [0mnum_examples[0m[0;34m)[0m[0;34m:[0m[0;34m[0m[0;34m[0m[0m
[1;32m      4[0m     [0;34m'''generate y = Xw + b + noise'''[0m[0;34m[0m[0;34m[0m[0m
[1;32m      5[0m     [0mX[0m [0;34m=[0m [0mnp[0m[0;34m.[0m[0mrandom[0m[0;34m.[0m[0mnormal[0m[0;34m([0m[0mscale[0m[0;34m=[0m[0;36m1[0m[0;34m,[0m [0msize[0m[0;34m=[0m[0;34m([0m[0mnum_examples[0m[0;34m,[0m [0mlen[0m[0;34m([0m[0mw[0m[0;34m)[0m[0;34m)[0m[0;34m)[0m[0;34m[0m[0;34m[0m[0m

[0;31mModuleNotFoundError[0m: No module named 'torch'
ModuleNotFoundError: No module named 'torch'

